Workbook

Sheet Read Me
A1: TrueNorth — Brokerage and Property Management Pro Forma
A4: HOW TO USE THIS MODEL
A5: Blue numbers are inputs you can change. Black numbers are formulas — do not type over them.
A6: Yellow cells are the two switches that drive everything: the scenario on Scenarios!B3 and the fee
A7: architecture on Tiers!B3.
A9: THE PROBLEM THIS MODEL WAS BUILT TO ANSWER
A10: At $399 per transaction with the listing marketing package included, a listing-side deal costs the
A11: brokerage more than it collects. The media package (photography, aerial, edited video, floor plan,
A12: flyers, sign, lockbox) is modeled at roughly $500-750 per listing on the Costs tab. The brokerage
A13: collects $399. Every listing an agent takes is therefore a loss before a single fixed cost is paid,
A14: and the harder an agent works, the more the brokerage loses. That is not a pricing problem at the
A15: margin; it is the wrong shape of deal.
... A37: labeled and every one is editable.

Sheet Scenarios
A1: Scenarios
A2: Pick one in B3. Every other tab follows it.
A3: Selected scenario | B3: Modest
A5: Driver | B5: Conservative | C5: Modest | D5: Aggressive | E5: Active | F5: Note
A6: Agents at start (incl. you and your mother) | B6: 2 | C6: 2 | D6: 2 | E6: =INDEX(B6:D6,MATCH($B$3,$B$5:$D$5,0)) | F6: You and your mother on day one.
A7: Net new agents per month, months 1-12 | B7: 0.5 | C7: 1 | D7: 2 | E7: =INDEX(B7:D7,MATCH($B$3,$B$5:$D$5,0)) | F7: Recruiting is the whole game. 1/mo is a believable pace for a new brokerage with a referral-based pitch.
A8: Net new agents per month, months 13-24 | B8: 1 | C8: 2 | D8: 3.5 | E8: =INDEX(B8:D8,MATCH($B$3,$B$5:$D$5,0)) | F8: Assumes word of mouth compounds once agents are paid on time.
A9: Annual agent attrition | B9: 0.2 | C9: 0.25 | D9: 0.3 | E9: =INDEX(B9:D9,MATCH($B$3,$B$5:$D$5,0)) | F9: Industry churn is high. Faster growth usually means looser screening, so attrition rises with the case.
A10: Transactions per agent per month | B10: 0.35 | C10: 0.5 | D10: 0.7 | E10: =INDEX(B10:D10,MATCH($B$3,$B$5:$D$5,0)) | F10: 0.5 = six closings a year per agent. The NAR median is in that range; be honest here.
A11: Share of transactions that are listing side | B11: 0.35 | C11: 0.45 | D11: 0.55 | E11: =INDEX(B11:D11,MATCH($B$3,$B$5:$D$5,0)) | F11: Listings are the expensive side to serve because of media.
A12: Average sale price | B12: 285000 | C12: 310000 | D12: 340000 | E12: =INDEX(B12:D12,MATCH($B$3,$B$5:$D$5,0)) | F12: Hernando County range. Drives the agent's gross, not your fee.
A13: Media package attach rate on listings | B13: 1 | C13: 0.85 | D13: 0.75 | E13: =INDEX(B13:D13,MATCH($B$3,$B$5:$D$5,0)) | F13: Not every listing gets the full package; land and teardowns do not need video.
A14: Tier mix — Solo | B14: 0.6 | C14: 0.5 | D14: 0.4 | E14: =INDEX(B14:D14,MATCH($B$3,$B$5:$D$5,0)) | F14: Used only when the Tiered architecture is selected.
A15: Tier mix — Pro | B15: 0.3 | C15: 0.35 | D15: 0.4 | E15: =INDEX(B15:D15,MATCH($B$3,$B$5:$D$5,0))
A16: Tier mix — Premier | B16: 0.1 | C16: 0.15 | D16: 0.2 | E16: =INDEX(B16:D16,MATCH($B$3,$B$5:$D$5,0))
A17: PM doors at start | B17: 3 | C17: 5 | D17: 8 | E17: =INDEX(B17:D17,MATCH($B$3,$B$5:$D$5,0)) | F17: Units under management today.
A18: PM doors added per month | B18: 1 | C18: 2 | D18: 3.5 | E18: =INDEX(B18:D18,MATCH($B$3,$B$5:$D$5,0)) | F18: The property management book is the asset. See PM and EV.
A19: PM monthly fee per door | B19: 129 | C19: 149 | D19: 169 | E19: =INDEX(B19:D19,MATCH($B$3,$B$5:$D$5,0)) | F19: Blended across Essential/Plus/Premier.
A21: Tier mix must total 100% | E21: =SUM(E14:E16)

Sheet Tiers
A1: Fee architecture
A2: Switch architectures in B3. The tier table below drives the Tiered case.
A3: Selected architecture | B3: B. Tiered
A5: Tier | B5: Solo | C5: Pro | D5: Premier | E5: What it is
A6: Monthly fee | B6: 29 | C6: 99 | D6: 299 | E6: Covers the seat: compliance, escrow, supervision, e-signature, transaction management.
A7: Transaction fee | B7: 495 | C7: 425 | D7: 350 | E7: Falls as the monthly rises. An agent who closes a lot should prefer Premier; that is the point.
A8: Media credit per listing | B8: 0 | C8: 300 | D8: 500 | E8: What the brokerage funds toward the listing media package. Agent pays any excess.
A9: CRM seat included | B9: 0 | C9: 1 | D9: 1 | E9: 1 = yes. Cost per seat is on the Costs tab.
A10: Transaction coordination included | B10: 0 | C10: 0 | D10: 0 | E10: 1 = yes. Left at 0 on every tier: a $325 coordinator inside a $350 transaction fee erases the fee. Sell it as a $395 add-on instead.
A12: Flat architectures (A and C)
A13: Flat monthly fee | B13: 20 | E13: Your current plan.
A14: Flat transaction fee | B14: 399 | E14: Your current plan.
A15: Media credit per listing — A | B15: 750 | E15: Architecture A includes the full package, so the brokerage funds all of it.
A16: Media credit per listing — C | B16: 0 | E16: Architecture C bills media to the agent at cost. Same $399, no hole.
A17: Monthly fee — D (in-house media) | B17: 99 | E17: The per-seat tech stack costs about $83 a month. A $20 fee cannot cover it; this one can.
A18: Transaction fee — D | B18: 399 | E18: Your number, kept.
A20: Blended economics at the selected architecture and scenario
A21: Blended monthly fee per agent | B21: =IF($B$3="B. Tiered",B6*Scenarios!$E$14+C6*Scenarios!$E$15+D6*Scenarios!$E$16,IF($B$3="D. In-house media",B17,B13))
A22: Blended transaction fee | B22: =IF($B$3="B. Tiered",B7*Scenarios!$E$14+C7*Scenarios!$E$15+D7*Scenarios!$E$16,IF($B$3="D. In-house media",B18,B14))
A23: Blended media credit per listing | B23: =IF($B$3="B. Tiered",B8*Scenarios!$E$14+C8*Scenarios!$E$15+D8*Scenarios!$E$16,IF(OR($B$3="A. Flat (current)",$B$3="D. In-house media"),B15,B16))
A24: Share of agents with CRM seat included | B24: =IF($B$3="B. Tiered",C9*Scenarios!$E$15+D9*Scenarios!$E$16,1)
A25: Share of transactions with TC included | B25: =IF($B$3="B. Tiered",D10*Scenarios!$E$16,0)

Sheet Costs
A1: Cost build-up
A2: Market estimates, not quotes. Replace with real numbers before you commit to a price.
A3: Listing media package — per listing
A4: Professional photography | B4: 175 | C4: Local real estate shooter, 30-40 images.
A5: Aerial photos and video | B5: 125 | C5: Requires an FAA Part 107 pilot. Your cost if you hire one; near zero if you certify yourself.
A6: Edited listing video | B6: 200 | C6: Walkthrough, cut for social.
A7: Floor plan | B7: 75 | C7: Usually bundled with the photo shoot.
A8: Printed flyers and brochures | B8: 60 | C8: Short run, per listing.
A9: Yard sign and install | B9: 60 | C9: Amortized over roughly 4 listings per sign.
A10: Lockbox | B10: 25 | C10: Amortized. Electronic boxes run $100-150 and last years.
A11: Total media package per listing | B11: =SUM(B4:B10) | C11: This is the number that breaks a $399 flat fee.
A13: In-house media — you shoot it yourself
A14: Editing, per listing | B14: 65 | C14: Your quoted editor rate for photos and video.
A15: Printed flyers and brochures | B15: 60 | C15: Still a print cost whoever shoots it.
A16: Yard sign and lockbox, amortized | B16: 85 | C16: Unchanged — you are not shooting these.
A17: Your hours per listing | B17: 2.5 | C17: Drive, shoot interior and exterior, fly the drone, upload, review the edit.
A18: Value of your hour | B18: 75 | C18: What an hour of your time is worth doing the next best thing: recruiting an agent or signing a door.
A19: In-house media, cash cost per listing | B19: =SUM(B14:B16) | C19: What actually leaves the bank account.
A20: In-house media, loaded cost per listing | B20: =B19+B17*B18 | C20: Cash plus your time. This is the honest number to price against.
A21: Listings you can personally shoot per month | B21: 10 | C21: Above this, you outsource the overflow at the full package price — or stop taking listings.
A22: Count your time as a cost? | B22: 1 | C22: 1 = yes (recommended). 0 = treat your labor as free and see the flattering version.
A23: Active media cost per listing | B23: =IF(Tiers!$B$3="D. In-house media",IF(Costs!$B$22=1,Costs!$B$20,Costs!$B$19),Costs!$B$11) | C23: What the P&L and unit economics use.
A25: Fixed monthly — the brokerage exists whether or not anyone closes
A26: Brokerage E&O policy | B26: 150 | C26: Firm policy. Agents carry their own on top.
A27: General liability | B27: 45
A28: Broker association and MLS dues | B28: 85 | C28: Your own dues, annualized to a month.
A29: Website, hosting, domain, email | B29: 35
A30: Transaction management platform | B30: 85 | C30: Base tier for a small firm.
A31: E-signature | B31: 45 | C31: DocuSign Business Pro is about $45/user/month annually — needed for PowerForms.
A32: Accounting and bookkeeping | B32: 250 | C32: Trust accounting is not a DIY job once agents are closing.
A33: Legal and compliance retainer | B33: 125 | C33: Annual attorney review amortized.
A34: Phone system and call routing | B34: 35
A35: Banking, escrow account fees, software | B35: 40
A36: Marketing and recruiting spend | B36: 200 | C36: Cards, cap hats, event table fees, boosted posts.
A37: Total fixed monthly | B37: =SUM(B26:B36)
A39: Per agent, per month
A40: CRM seat | B40: 65 | C40: Follow Up Boss class tool. Only charged for tiers that include it.
A41: Email, storage, phone line | B41: 18 | C41: Charged for every agent.
A43: Per transaction
A44: Compliance review and file handling | B44: 35 | C44: Your time, costed. It is not free just because you do it.
...

Sheet P&L
A1: Brokerage P&L — 24 months
A2: Brokerage only. Property management is modeled separately on PM and EV.
A4: Month | B4: 1 | C4: 2 | D4: 3 | E4: 4 | F4: 5 | G4: 6 | H4: 7 | I4: 8 | J4: 9 | K4: 10 | L4: 11 | M4: 12 | N4: 13 | O4: 14 | P4: 15 | Q4: 16 | R4: 17 | S4: 18 | T4: 19 | U4: 20 | V4: 21 | W4: 22 | X4: 23 | Y4: 24 | Z4: Year 1 + 2
A5: Agents
A6: Agents, start of month | B6: =Scenarios!$E$6 | C6: =B7 | D6: =C7 | E6: =D7 | F6: =E7 | G6: =F7 | H6: =G7 | I6: =H7 | J6: =I7 | ... Y6: =X7
A7: Agents, end of month | B7: =MAX(0,B6+IF(1<=12,Scenarios!$E$7,Scenarios!$E$8)-B6*Scenarios!$E$9/12) | C7: =MAX(0,C6+IF(2<=12,Scenarios!$E$7,Scenarios!$E$8)-C6*Scenarios!$E$9/12) | D7: =MAX(0,D6+IF(3<=12,Scenarios!$E$7,Scenarios!$E$8)-D6*Scenarios!$E$9/12) | E7: =MAX(0,E6+IF(4<=12,Scenarios!$E$7,Scenarios!$E$8)-E6*Scenarios!$E$9/12) | F7: =MAX(0,F6+IF(5<=12,Scenarios!$E$7,Scenarios!$E$8)-F6*Scenarios!$E$9/12) | G7: =MAX(0,G6+IF(6<=12,Scenarios!$E$7,Scenarios!$E$8)-G6*Scenarios!$E$9/12) | H7: =MAX(0,H6+IF(7<=12,Scenarios!$E$7,Scenarios!$E$8)-H6*Scenarios!$E$9/12) | I7: =MAX(0,I6+IF(8<=12,Scenarios!$E$7,Scenarios!$E$8)-I6*Scenarios!$E$9/12) | J7: =MAX(0,J6+IF(9<=12,Scenarios!$E$7,Scenarios!$E$8)-J6*Scenarios!$E$9/12) | K7: =MAX(0,K6+IF(10<=12,Scenarios!$E$7,Scenarios!$E$8)-K6*Scenarios!$E$9/12) | L7: =MAX(0,L6+IF(11<=12,Scenarios!$E$7,Scenarios!$E$8)-L6*Scenarios!$E$9/12) | M7: =MAX(0,M6+IF(12<=12,Scenarios!$E$7,Scenarios!$E$8)-M6*Scenarios!$E$9/12) | N7: =MAX(0,N6+IF(13<=12,Scenarios!$E$7,Scenarios!$E$8)-N6*Scenarios!$E$9/12) | O7: =MAX(0,O6+IF(14<=12,Scenarios!$E$7,Scenarios!$E$8)-O6*Scenarios!$E$9/12) | P7: =MAX(0,P6+IF(15<=12,Scenarios!$E$7,Scenarios!$E$8)-P6*Scenarios!$E$9/12) | Q7: =MAX(0,Q6+IF(16<=12,Scenarios!$E$7,Scenarios!$E$8)-Q6*Scenarios!$E$9/12) | R7: =MAX(0,R6+IF(17<=12,Scenarios!$E$7,Scenarios!$E$8)-R6*Scenarios!$E$9/12) | S7: =MAX(0,S6+IF(18<=12,Scenarios!$E$7,Scenarios!$E$8)-S6*Scenarios!$E$9/12) | T7: =MAX(0,T6+IF(19<=12,Scenarios!$E$7,Scenarios!$E$8)-T6*Scenarios!$E$9/12) | U7: =MAX(0,U6+IF(20<=12,Scenarios!$E$7,Scenarios!$E$8)-U6*Scenarios!$E$9/12) | V7: =MAX(0,V6+IF(21<=12,Scenarios!$E$7,Scenarios!$E$8)-V6*Scenarios!$E$9/12) | W7: =MAX(0,W6+IF(22<=12,Scenarios!$E$7,Scenarios!$E$8)-W6*Scenarios!$E$9/12) | X7: =MAX(0,X6+IF(23<=12,Scenarios!$E$7,Scenarios!$E$8)-X6*Scenarios!$E$9/12) | Y7: =MAX(0,Y6+IF(24<=12,Scenarios!$E$7,Scenarios!$E$8)-Y6*Scenarios!$E$9/12) | Z7: =Y7
A8: Transactions closed | B8: =B7*Scenarios!$E$10 | C8: =C7*Scenarios!$E$10 | D8: =D7*Scenarios!$E$10 | E8: =E7*Scenarios!$E$10 | F8: =F7*Scenarios!$E$10 | G8: =G7*Scenarios!$E$10 | H8: =H7*Scenarios!$E$10 | I8: =I7*Scenarios!$E$10 | ... Y8: =Y7*Scenarios!$E$10 | Z8: =SUM(B8:Y8)
A9: Listing-side transactions | B9: =B8*Scenarios!$E$11 | C9: =C8*Scenarios!$E$11 | D9: =D8*Scenarios!$E$11 | E9: =E8*Scenarios!$E$11 | F9: =F8*Scenarios!$E$11 | G9: =G8*Scenarios!$E$11 | H9: =H8*Scenarios!$E$11 | I9: =I8*Scenarios!$E$11 | ... Y9: =Y8*Scenarios!$E$11 | Z9: =SUM(B9:Y9)
A10: Listings taking the media package | B10: =B9*Scenarios!$E$13 | C10: =C9*Scenarios!$E$13 | D10: =D9*Scenarios!$E$13 | E10: =E9*Scenarios!$E$13 | F10: =F9*Scenarios!$E$13 | G10: =G9*Scenarios!$E$13 | H10: =H9*Scenarios!$E$13 | I10: =I9*Scenarios!$E$13 | ... Y10: =Y9*Scenarios!$E$13 | Z10: =SUM(B10:Y10)
A12: Revenue
A13: Membership fees | B13: =B7*Tiers!$B$21 | C13: =C7*Tiers!$B$21 | D13: =D7*Tiers!$B$21 | E13: =E7*Tiers!$B$21 | F13: =F7*Tiers!$B$21 | G13: =G7*Tiers!$B$21 | H13: =H7*Tiers!$B$21 | I13: =I7*Tiers!$B$21 | ... Y13: =Y7*Tiers!$B$21 | Z13: =SUM(B13:Y13)
A14: Transaction fees | B14: =B8*Tiers!$B$22 | C14: =C8*Tiers!$B$22 | D14: =D8*Tiers!$B$22 | E14: =E8*Tiers!$B$22 | F14: =F8*Tiers!$B$22 | G14: =G8*Tiers!$B$22 | H14: =H8*Tiers!$B$22 | I14: =I8*Tiers!$B$22 | ... Y14: =Y8*Tiers!$B$22 | Z14: =SUM(B14:Y14)
A15: Media billed to agents above credit | B15: =B10*MAX(0,Costs!$B$23-Tiers!$B$23) | C15: =C10*MAX(0,Costs!$B$23-Tiers!$B$23) | D15: =D10*MAX(0,Costs!$B$23-Tiers!$B$23) | E15: =E10*MAX(0,Costs!$B$23-Tiers!$B$23) | F15: =F10*MAX(0,Costs!$B$23-Tiers!$B$23) | G15: =G10*MAX(0,Costs!$B$23-Tiers!$B$23) | H15: =H10*MAX(0,Costs!$B$23-Tiers!$B$23) | I15: =I10*MAX(0,Costs!$B$23-Tiers!$B$23) | ... Y15: =Y10*MAX(0,Costs!$B$23-Tiers!$B$23) | Z15: =SUM(B15:Y15)
A16: Total revenue | B16: =SUM(B13:B15) | C16: =SUM(C13:C15) | D16: =SUM(D13:D15) | E16: =SUM(E13:E15) | F16: =SUM(F13:F15) | G16: =SUM(G13:G15) | H16: =SUM(H13:H15) | I16: =SUM(I13:I15) | ... Y16: =SUM(Y13:Y15) | Z16: =SUM(B16:Y16)
A18: Cost of service
A19: Listings above your shooting capacity | B19: =IF(Tiers!$B$3="D. In-house media",MAX(0,B10-Costs!$B$21),0) | C19: =IF(Tiers!$B$3="D. In-house media",MAX(0,C10-Costs!$B$21),0) | D19: =IF(Tiers!$B$3="D. In-house media",MAX(0,D10-Costs!$B$21),0) | E19: =IF(Tiers!$B$3="D. In-house media",MAX(0,E10-Costs!$B$21),0) | F19: =IF(Tiers!$B$3="D. In-house media",MAX(0,F10-Costs!$B$21),0) | G19: =IF(Tiers!$B$3="D. In-house media",MAX(0,G10-Costs!$B$21),0) | H19: =IF(Tiers!$B$3="D. In-house media",MAX(0,H10-Costs!$B$21),0) | I19: =IF(Tiers!$B$3="D. In-house media",MAX(0,I10-Costs!$B$21),0) | ... Y19: =IF(Tiers!$B$3="D. In-house media",MAX(0,Y10-Costs!$B$21),0) | Z19: =SUM(B19:Y19)
A20: Media cost | B20: =MIN(B10,IF(Tiers!$B$3="D. In-house media",Costs!$B$21,B10))*Costs!$B$23+B19*Costs!$B$11 | C20: =MIN(C10,IF(Tiers!$B$3="D. In-house media",Costs!$B$21,C10))*Costs!$B$23+C19*Costs!$B$11 | D20: =MIN(D10,IF(Tiers!$B$3="D. In-house media",Costs!$B$21,D10))*Costs!$B$23+D19*Costs!$B$11 | E20: =MIN(E10,IF(Tiers!$B$3="D. In-house media",Costs!$B$21,E10))*Costs!$B$23+E19*Costs!$B$11 | F20: =MIN(F10,IF(Tiers!$B$3="D. In-house media",Costs!$B$21,F10))*Costs!$B$23+F19*Costs!$B$11 | G20: =MIN(G10,IF(Tiers!$B$3="D. In-house media",Costs!$B$21,G10))*Costs!$B$23+G19*Costs!$B$11 | H20: =MIN(H10,IF(Tiers!$B$3="D. In-house media",Costs!$B$21,H10))*Costs!$B$23+H19*Costs!$B$11 | I20: =MIN(I10,IF(Tiers!$B$3="D. In-house media",Costs!$B$21,I10))*Costs!$B$23+I19*Costs!$B$11 | ... Y20: =MIN(Y10,IF(Tiers!$B$3="D. In-house media",Costs!$B$21,Y10))*Costs!$B$23+Y19*Costs!$B$11 | Z20: =SUM(B20:Y20)
A21: Per-transaction cost | B21: =B8*((Costs!$B$44+Costs!$B$45)+Tiers!$B$25*Costs!$B$46) | C21: =C8*((Costs!$B$44+Costs!$B$45)+Tiers!$B$25*Costs!$B$46) | D21: =D8*((Costs!$B$44+Costs!$B$45)+Tiers!$B$25*Costs!$B$46) | E21: =E8*((Costs!$B$44+Costs!$B$45)+Tiers!$B$25*Costs!$B$46) | F21: =F8*((Costs!$B$44+Costs!$B$45)+Tiers!$B$25*Costs!$B$46) | G21: =G8*((Costs!$B$44+Costs!$B$45)+Tiers!$B$25*Costs!$B$46) | H21: =H8*((Costs!$B$44+Costs!$B$45)+Tiers!$B$25*Costs!$B$46) | I21: =I8*((Costs!$B$44+Costs!$B$45)+Tiers!$B$25*Costs!$B$46) | ... Y21: =Y8*((Costs!$B$44+Costs!$B$45)+Tiers!$B$25*Costs!$B$46) | Z21: =SUM(B21:Y21)
A22: Per-agent cost | B22: =B7*(Costs!$B$41+Tiers!$B$24*Costs!$B$40) | C22: =C7*(Costs!$B$41+Tiers!$B$24*Costs!$B$40) | D22: =D7*(Costs!$B$41+Tiers!$B$24*Costs!$B$40) | E22: =E7*(Costs!$B$41+Tiers!$B$24*Costs!$B$40) | F22: =F7*(Costs!$B$41+Tiers!$B$24*Costs!$B$40) | G22: =G7*(Costs!$B$41+Tiers!$B$24*Costs!$B$40) | H22: =H7*(Costs!$B$41+Tiers!$B$24*Costs!$B$40) | I22: =I7*(Costs!$B$41+Tiers!$B$24*Costs!$B$40) | ... Y22: =Y7*(Costs!$B$41+Tiers!$B$24*Costs!$B$40) | Z22: =SUM(B22:Y22)
A23: Fixed overhead | B23: =Costs!$B$37 | C23: =Costs!$B$37 | D23: =Costs!$B$37 | E23: =Costs!$B$37 | F23: =Costs!$B$37 | G23: =Costs!$B$37 | H23: =Costs!$B$37 | I23: =Costs!$B$37 | ... Y23: =Costs!$B$37 | Z23: =SUM(B23:Y23)
A24: Managing agent compensation | B24: ='Managing Agent'!B$30 | C24: ='Managing Agent'!C$30 | D24: ='Managing Agent'!D$30 | E24: ='Managing Agent'!E$30 | F24: ='Managing Agent'!F$30 | G24: ='Managing Agent'!G$30 | H24: ='Managing Agent'!H$30 | I24: ='Managing Agent'!I$30 | ... Y24: ='Managing Agent'!Y$30 | Z24: =SUM(B24:Y24)
A25: Total cost | B25: =SUM(B20:B24) | C25: =SUM(C20:C24) | D25: =SUM(D20:D24) | E25: =SUM(E20:E24) | F25: =SUM(F20:F24) | G25: =SUM(G20:G24) | H25: =SUM(H20:H24) | I25: =SUM(I20:I24) | ... Y25: =SUM(Y20:Y24) | Z25: =SUM(B25:Y25)
A27: EBITDA | B27: =B16-B25 | C27: =C16-C25 | D27: =D16-D25 | E27: =E16-E25 | F27: =F16-F25 | G27: =G16-G25 | H27: =H16-H25 | I27: =I16-I25 | ... Y27: =Y16-Y25 | Z27: =SUM(B27:Y27)
A28: Cumulative EBITDA | B28: =B27 | C28: =B28+C27 | D28: =C28+D27 | E28: =D28+E27 | F28: =E28+F27 | G28: =F28+G27 | H28: =G28+H27 | I28: =H28+I27 | J28: =I28+J27 | ... Y28: =X28+Y27 | Z28: =Y28
A29: EBITDA margin | B29: =IFERROR(B27/B16,0) | C29: =IFERROR(C27/C16,0) | D29: =IFERROR(D27/D16,0) | E29: =IFERROR(E27/E16,0) | F29: =IFERROR(F27/F16,0) | G29: =IFERROR(G27/G16,0) | H29: =IFERROR(H27/H16,0) | I29: =IFERROR(I27/I16,0) | ... Z29: =IFERROR(Z27/Z16,0)

Sheet Unit Economics
A1: Unit economics
A2: What one transaction and one agent are actually worth at the selected architecture.
A3: Per transaction
A4: Revenue — transaction fee | B4: =Tiers!$B$22
A5: Cost — compliance, file, banking | B5: =-(Costs!$B$44+Costs!$B$45)
A6: Cost — transaction coordination (weighted) | B6: =-Tiers!$B$25*Costs!$B$46
A7: Contribution — buyer-side transaction | B7: =SUM(B4:B6) | D7: No media on the buyer side. This is the profitable half.
A9: Media package cost per listing | B9: =-Costs!$B$23
A10: Media billed back to the agent | B10: =MAX(0,Costs!$B$23-Tiers!$B$23)
A11: Contribution — listing-side transaction | B11: =B7+B9+B10 | D11: Negative here means every listing is a loss. That is the test.
A13: Blended contribution per transaction | B13: =B7*(1-Scenarios!$E$11)+B11*Scenarios!$E$11
A15: Per agent, per month
A16: Membership fee | B16: =Tiers!$B$21
A17: Seat cost | B17: =-(Costs!$B$41+Tiers!$B$24*Costs!$B$40)
A18: Contribution from transactions | B18: =Scenarios!$E$10*B13
A19: Contribution per agent per month | B19: =SUM(B16:B18)
A20: Contribution per agent per year | B20: =B19*12
A22: Break-even
A23: Fixed overhead per month | B23: =Costs!$B$37
A24: Managing agent cost per month (year 1 average) | B24: =AVERAGE('Managing Agent'!B30:M30)
A25: Agents required to break even | B25: =IF(B19<=0,"never",(B23+B24)/B19) | D25: If this says never, the architecture loses money on every agent and no amount of recruiting fixes it.
A26: Transactions per month required to break even | B26: =IF(B13<=0,"never",(B23+B24)/B13)

Sheet Managing Agent
A1: Paying the managing agent
A2: Three structures. Switch in B3. Row 30 feeds the P&L.
A3: Selected structure | B3: 2. Override + mentor split
A5: Recruiting override per closed transaction | B5: 60 | D5: Paid on every transaction closed by an agent she recruited, for the life of that agent.
A6: Share of agents credited to her recruiting | B6: 0.7 | D6: She is the recruiter; you are the broker. Be honest about who sources whom.
A7: Mentor split — share of mentee commission | B7: 0.2 | D7: Paid by the MENTEE out of their own commission, not by the brokerage. The brokerage collects and passes it through.
A8: Mentee transactions covered | B8: 3 | D8: First three closings. After that the agent is on their own.
A9: Share of new agents needing a mentor | B9: 0.5 | D9: Newly licensed or returning agents.
A10: Average commission per side to the agent | B10: 7750 | D10: 2.5% of the average sale price. Drives the mentor split.
A11: Monthly base (structure 3 only) | B11: 1500 | D11: See the note below before you choose this.
A13: A fixed monthly base is the one that can cost you the 1099
A14: IRC s. 3508 requires that substantially all of a real estate agent's pay be tied to output rather than hours.
A15: A flat monthly base paid to a licensed agent cuts against that, and if her classification falls, every agent's
A16: classification is open to the same question. If you want to pay her a base, pay it to an entity she forms for
A17: management services, under a separate written agreement, and keep it away from her license income.
A20: Month | B20: 1 | C20: 2 | D20: 3 | E20: 4 | F20: 5 | G20: 6 | H20: 7 | I20: 8 | J20: 9 | K20: 10 | L20: 11 | M20: 12 | N20: 13 | O20: 14 | P20: 15 | Q20: 16 | R20: 17 | S20: 18 | T20: 19 | U20: 20 | V20: 21 | W20: 22 | X20: 23 | Y20: 24 | Z20: Total
A21: Transactions by her recruits | B21: =P&L!B8*$B$6 | C21: =P&L!C8*$B$6 | D21: =P&L!D8*$B$6 | E21: =P&L!E8*$B$6 | F21: =P&L!F8*$B$6 | G21: =P&L!G8*$B$6 | H21: =P&L!H8*$B$6 | I21: =P&L!I8*$B$6 | ... Y21: =P&L!Y8*$B$6 | Z21: =SUM(B21:Y21)
A22: Recruiting override | B22: =B21*$B$5 | C22: =C21*$B$5 | D22: =D21*$B$5 | E22: =E21*$B$5 | F22: =F21*$B$5 | G22: =G21*$B$5 | H22: =H21*$B$5 | I22: =I21*$B$5 | ... Y22: =Y21*$B$5 | Z22: =SUM(B22:Y22)
A23: New agents this month | B23: =0 | C23: =MAX(0,P&L!C7-P&L!B7) | D23: =MAX(0,P&L!D7-P&L!C7) | E23: =MAX(0,P&L!E7-P&L!D7) | F23: =MAX(0,P&L!F7-P&L!E7) | G23: =MAX(0,P&L!G7-P&L!F7) | H23: =MAX(0,P&L!H7-P&L!G7) | I23: =MAX(0,P&L!I7-P&L!H7) | J23: =MAX(0,P&L!J7-P&L!I7) | ... Y23: =MAX(0,P&L!Y7-P&L!X7) | Z23: =SUM(B23:Y23)
A24: Mentor split earned | B24: =B23*$B$9*$B$8*$B$10*$B$7 | C24: =C23*$B$9*$B$8*$B$10*$B$7 | D24: =D23*$B$9*$B$8*$B$10*$B$7 | E24: =E23*$B$9*$B$8*$B$10*$B$7 | F24: =F23*$B$9*$B$8*$B$10*$B$7 | G24: =G23*$B$9*$B$8*$B$10*$B$7 | H24: =H23*$B$9*$B$8*$B$10*$B$7 | I24: =I23*$B$9*$B$8*$B$10*$B$7 | ... Y24: =Y23*$B$9*$B$8*$B$10*$B$7 | Z24: =SUM(B24:Y24)
A25: Base, if selected | B25: =IF($B$3="3. Base + override",$B$11,0) | C25: =IF($B$3="3. Base + override",$B$11,0) | D25: =IF($B$3="3. Base + override",$B$11,0) | E25: =IF($B$3="3. Base + override",$B$11,0) | F25: =IF($B$3="3. Base + override",$B$11,0) | G25: =IF($B$3="3. Base + override",$B$11,0) | H25: =IF($B$3="3. Base + override",$B$11,0) | I25: =IF($B$3="3. Base + override",$B$11,0) | ... Y25: =IF($B$3="3. Base + override",$B$11,0) | Z25: =SUM(B25:Y25)
A26: Memo: mentor split paid by mentees (pass-through, not a brokerage cost) | B26: =B24 | C26: =C24 | D26: =D24 | E26: =E24 | F26: =F24 | G26: =G24 | H26: =H24 | I26: =I24 | ... Y26: =Y24 | Z26: =SUM(B26:Y26)
A30: Total cost to the brokerage | B30: =IF($B$3="3. Base + override",B22+B25,B22) | C30: =IF($B$3="3. Base + override",C22+C25,C22) | D30: =IF($B$3="3. Base + override",D22+D25,D22) | E30: =IF($B$3="3. Base + override",E22+E25,E22) | F30: =IF($B$3="3. Base + override",F22+F25,F22) | G30: =IF($B$3="3. Base + override",G22+G25,G22) | H30: =IF($B$3="3. Base + override",H22+H25,H22) | I30: =IF($B$3="3. Base + override",I22+I25,I22) | ... Y30: =IF($B$3="3. Base + override",Y22+Y25,Y22) | Z30: =SUM(B30:Y30)
A32: Her total earnings, including her own production
A33: Her own transactions per month | B33: =Scenarios!$E$10 | D33: She is also an agent paying the same fees as everyone else.
A34: Her commission income per year | B34: =B33*12*$B$10
A35: Her management income, year 1 | B35: =SUM(B30:M30)+SUM(B26:M26) | D35: Override from the brokerage plus mentor splits paid by her mentees.
A36: Her fees paid to the brokerage per year | B36: =-(12*Tiers!$B$21+B33*12*Tiers!$B$22)
A37: Net to her, year 1 | B37: =B34+B35+B36

Sheet PM and EV
A1: Property management and enterprise value
A2: Where the durable value actually sits.
A3: Property management, 24 months
A4: Doors at start | B4: =Scenarios!$E$17
A5: Doors added per month | B5: =Scenarios!$E$18
A6: Doors at month 24 | B6: =B4+B5*24
A7: Monthly fee per door | B7: =Scenarios!$E$19
A8: Annual recurring management revenue at month 24 | B8: =B6*B7*12
A9: Leasing fees per year | B9: =B6*0.4*0.75*Scenarios!$E$19*6 | E9: Rough: 40% of doors turn in a year, leasing fee of 75% of a month's rent. Replace with your real numbers.
A10: PM direct costs | B10: 0.35 | E10: Share of PM revenue consumed by software, inspections, and your time.
A11: PM contribution per year | B11: =(B8+B9)*(1-B10)
A13: What each business is worth
B14: Low | C14: Mid | D14: High | E14: Basis
A15: Brokerage — multiple of EBITDA | B15: 1.5 | C15: 2.5 | D15: 3.5 | E15: Small independent brokerages trade low. Agent rosters walk, and fee income is not contracted.
A16: Brokerage EBITDA, year 2 run rate | B16: =SUM('P&L'!N27:Y27)
A17: Brokerage value | B17: =MAX(0,$B$16*B15) | C17: =MAX(0,$B$16*C15) | D17: =MAX(0,$B$16*D15)
A19: PM — multiple of annual recurring revenue | B19: 1.2 | C19: 1.8 | D19: 2.5 | E19: Management contracts recur and transfer with a sale, which is why PM books trade on revenue, not earnings.
A20: PM annual recurring revenue | B20: =B8
A21: PM value | B21: =$B$20*B19 | C21: =$B$20*C19 | D21: =$B$20*D19
A23: Combined enterprise value | B23: =B17+B21 | C23: =C17+C21 | D23: =D17+D21
A24: PM share of total value | B24: =IFERROR(B21/(B17+B21),0) | C24: =IFERROR(C21/(C17+C21),0) | D24: =IFERROR(D21/(D17+D21),0) | E24: If this is most of the value, the brokerage's job is to feed the PM book, not to carry the company.
